Workbook

Sheet total_consolidated_data
A1: Publication title | B1: Conference | C1: Conference year | D1: Conference country | E1: Number of authors | F1: Country of first author (as per publication date) | G1: Number of references provided in the PDF | H1: Number of citations under Google Scholar | I1: Number of tables | J1: Number of figures and graphs | K1: DOI
A2: Blockchain Capabilities in Supply Chain Management: A Literature Review | B2: BIOTC | C2: 2023 | D2: Japan | E2: 3 | F2: China | G2: 49 | H2: 3 | I2: 2 | J2: 1 | K2: 10.1145/3625078.3625079
A3: Proof of Review: Trust Me, It’s Been Reviewed | B3: BIOTC | C3: 2023 | D3: Japan | E3: 3 | F3: USA | G3: 21 | H3: 1 | I3: 0 | J3: 5 | K3: 10.1145/3625078.3625082
A4: Examination on interoperability of blockchains by using ZK-rollups | B4: BIOTC | C4: 2023 | D4: Japan | E4: 2 | F4: Japan | G4: 14 | H4: 7 | I4: 3 | J4: 3 | K4: 10.1145/3625078.3625084
A5: A Secure and IoT-Enabled Data Sharing System Based on IPFS and IOTA Blockchain | B5: BIOTC | C5: 2023 | D5: Japan | E5: 5 | F5: Taiwan | G5: 15 | H5: 1 | I5: 2 | J5: 5 | K5: 10.1145/3625078.3625085
A6: Building Students’ Digital Footprints with Blockchain in PBL Activities | B6: BIOTC | C6: 2023 | D6: Japan | E6: 4 | F6: Russia | G6: 13 | H6: 0 | I6: 1 | J6: 4 | K6: 10.1145/3625078.3625087
A7: Text Mining of User Comments Based on Deep Learning | B7: BIOTC | C7: 2023 | D7: Japan | E7: 1 | F7: China | G7: 11 | H7: 0 | I7: 4 | J7: 2 | K7: 10.1145/3625078.3625088
A8: Zero-Knowledge Proofs based delegation authentication for Industrial Internet of Things in certificateless proxy signatures | B8: IoTSMS | C8: 2023 | D8: USA | E8: 5 | F8: Pakistan | G8: 18 | H8: 1 | I8: 1 | J8: 4 | K8: 10.1109/IOTSMS59855.2023.10325763
A9: An Adaptive Flow-based NIDS for Smart Home Networks Against Malware Behavior Using XGBoost combined with Rough Set Theory | B9: IoTSMS | C9: 2023 | D9: USA | E9: 2 | F9: USA | G9: 31 | H9: 2 | I9: 0 | J9: 6 | K9: 10.1109/IOTSMS59855.2023.10325714
A10: Reducing the travel time of passengers between bus stations in the city by using the smart subsystem of road side unit (RSU) in the high traffic intersections of Zanjan city | B10: IoTSMS | C10: 2023 | D10: USA | E10: 1 | F10: Iran | G10: 43 | H10: 1 | I10: 3 | J10: 9 | K10: 10.1109/IOTSMS59855.2023.10325689
A11: An IoT-based Smart Bathroom for Healthy Life | B11: IoTSMS | C11: 2023 | D11: USA | E11: 4 | F11: Taiwan | G11: 14 | H11: 0 | I11: 1 | J11: 11 | K11: 10.1109/IOTSMS59855.2023.10325760
A12: AI-Enabled Plastic Pollution Monitoring System for Toronto Waterways | B12: IoTSMS | C12: 2023 | D12: USA | E12: 4 | F12: Canada | G12: 33 | H12: 1 | I12: 0 | J12: 3 | K12: 10.1109/IOTSMS59855.2023.10325803
A13: Bolstering the Mobile Cloud: Addressing Emerging Threats and Strengthening Multi-Layered Defenses for Robust Mobile Security | B13: IoTSMS | C13: 2023 | D13: USA | E13: 1 | F13: USA | G13: 63 | H13: 0 | I13: 2 | J13: 0 | K13: 10.1109/IOTSMS59855.2023.10325824
... A253: Vision Paper: Computing behind Transparent Screen | B253: EWSN | C253: 2024 | D253: United Arab Emirates | E253: 2 | F253: Netherlands | G253: 35 | H253: 1 | I253: 0 | J253: 4 | K253: -

Sheet statistical_evaluation 
A1: Sl. No. | B1: Name of the Conference | C1: Year | D1: No. of Papers | E1: Number of citations under Google Scholar | F1: Number of references provided in the PDF | G1: Number of authors | H1: Number of tables | I1: Number of figures and graphs | J1: Country based author diversity | K1: Remarks
A2: 1 | B2: BIOTC | C2: 2023 | D2: =COUNTA(total_consolidated_data!A2:A7) -> 6 | E2: =SUM(total_consolidated_data!H2:H7) -> 12 | F2: =SUM(total_consolidated_data!G2:G7) -> 123 | G2: =SUM(total_consolidated_data!E2:E7) -> 18 | H2: =SUM(total_consolidated_data!I2:I7) -> 12 | I2: =SUM(total_consolidated_data!J2:J7) -> 20 | J2: =COUNTA(_xlfn.UNIQUE(total_consolidated_data!F2:F7)) -> 5 | K2: One paper has 7 citations.
A3: =A2+1 -> 2 | B3: BIOTC | C3: 2024 | D3: =COUNTA(total_consolidated_data!A180:A187) -> 8 | E3: =SUM(total_consolidated_data!H180:H187) -> 36 | F3: =SUM(total_consolidated_data!G180:G187) -> 229 | G3: =SUM(total_consolidated_data!E180:E187) -> 37 | H3: =SUM(total_consolidated_data!I180:I187) -> 18 | I3: =SUM(total_consolidated_data!J180:J187) -> 56 | J3: =COUNTA(_xlfn.UNIQUE(total_consolidated_data!F180:F187)) -> 6 | K3: One paper has 10 citations.
A4: =A3+1 -> 3 | B4: DCOSS-IoT | C4: 2023 | D4: =COUNTA(total_consolidated_data!A48:A53) -> 6 | E4: =SUM(total_consolidated_data!H48:H53) -> 73 | F4: =SUM(total_consolidated_data!G48:G53) -> 143 | G4: =SUM(total_consolidated_data!E48:E53) -> 39 | H4: =SUM(total_consolidated_data!I48:I53) -> 7 | I4: =SUM(total_consolidated_data!J48:J53) -> 44 | J4: =COUNTA(_xlfn.UNIQUE(total_consolidated_data!F48:F53)) -> 5 | K4: All the papers are cited for more than 7 times.
A5: =A4+1 -> 4 | B5: DCOSS-IoT | C5: 2024 | D5: =COUNTA(total_consolidated_data!A152:A179) -> 28 | E5: =SUM(total_consolidated_data!H152:H179) -> 174 | F5: =SUM(total_consolidated_data!G152:G179) -> 780 | G5: =SUM(total_consolidated_data!E152:E179) -> 95 | H5: =SUM(total_consolidated_data!I152:I179) -> 79 | I5: =SUM(total_consolidated_data!J152:J179) -> 166 | J5: =COUNTA(_xlfn.UNIQUE(total_consolidated_data!F152:F179)) -> 13 | K5: One paper has 63 citations.
A6: =A5+1 -> 5 | B6: EAI HealthyIOT | C6: 2023 | D6: =COUNTA(total_consolidated_data!A14:A19) -> 6 | E6: =SUM(total_consolidated_data!H14:H19) -> 4 | F6: =SUM(total_consolidated_data!G14:G19) -> 241 | G6: =SUM(total_consolidated_data!E14:E19) -> 19 | H6: =SUM(total_consolidated_data!I14:I19) -> 11 | I6: =SUM(total_consolidated_data!J14:J19) -> 18 | J6: =COUNTA(_xlfn.UNIQUE(total_consolidated_data!F14:F19)) -> 5 | K6: Four papers have no citations.
A7: =A6+1 -> 6 | B7: EWSN | C7: 2023 | D7: =COUNTA(total_consolidated_data!A197:A233) -> 37 | E7: =SUM(total_consolidated_data!H197:H233) -> 2 | F7: =SUM(total_consolidated_data!G197:G233) -> 1010 | G7: =SUM(total_consolidated_data!E197:E233) -> 137 | H7: =SUM(total_consolidated_data!I197:I233) -> 63 | I7: =SUM(total_consolidated_data!J197:J233) -> 269 | J7: =COUNTA(_xlfn.UNIQUE(total_consolidated_data!F197:F233)) -> 18 | K7: Only 2 papers has citiations.
A8: =A7+1 -> 7 | B8: EWSN | C8: 2024 | D8: =COUNTA(total_consolidated_data!A234:A253) -> 20 | E8: =SUM(total_consolidated_data!H234:H253) -> 4 | F8: =SUM(total_consolidated_data!G234:G253) -> 759 | G8: =SUM(total_consolidated_data!E234:E253) -> 88 | H8: =SUM(total_consolidated_data!I234:I253) -> 61 | I8: =SUM(total_consolidated_data!J234:J253) -> 221 | J8: =COUNTA(_xlfn.UNIQUE(total_consolidated_data!F234:F253)) -> 10 | K8: Only 4 papers has citiations.
A9: =A8+1 -> 8 | B9: ICIOT | C9: 2023 | D9: =COUNTA(total_consolidated_data!A36:A41) -> 6 | E9: =SUM(total_consolidated_data!H36:H41) -> 4 | F9: =SUM(total_consolidated_data!G36:G41) -> 164 | G9: =SUM(total_consolidated_data!E36:E41) -> 27 | H9: =SUM(total_consolidated_data!I36:I41) -> 6 | I9: =SUM(total_consolidated_data!J36:J41) -> 33 | J9: =COUNTA(_xlfn.UNIQUE(total_consolidated_data!F36:F41)) -> 2 | K9: Three papers have no citations.
A10: =A9+1 -> 9 | B10: ICIOT | C10: 2024 | D10: =COUNTA(total_consolidated_data!A188:A196) -> 9 | E10: =SUM(total_consolidated_data!H188:H196) -> 4 | F10: =SUM(total_consolidated_data!G188:G196) -> 219 | G10: =SUM(total_consolidated_data!E188:E196) -> 47 | H10: =SUM(total_consolidated_data!I188:I196) -> 22 | I10: =SUM(total_consolidated_data!J188:J196) -> 49 | J10: =COUNTA(_xlfn.UNIQUE(total_consolidated_data!F188:F196)) -> 5 | K10: Six papers have no citations.
A11: =A10+1 -> 10 | B11: IFIP-IoT | C11: 2023 | D11: =COUNTA(total_consolidated_data!A26:A35) -> 10 | E11: =SUM(total_consolidated_data!H26:H35) -> 37 | F11: =SUM(total_consolidated_data!G26:G35) -> 277 | G11: =SUM(total_consolidated_data!E26:E35) -> 32 | H11: =SUM(total_consolidated_data!I26:I35) -> 16 | I11: =SUM(total_consolidated_data!J26:J35) -> 53 | J11: =COUNTA(_xlfn.UNIQUE(total_consolidated_data!F26:F35)) -> 3 | K11: One paper has 9 citations.
A12: =A11+1 -> 11 | B12: IoTBDS | C12: 2023 | D12: =COUNTA(total_consolidated_data!A20:A25) -> 6 | E12: =SUM(total_consolidated_data!H20:H25) -> 11 | F12: =SUM(total_consolidated_data!G20:G25) -> 201 | G12: =SUM(total_consolidated_data!E20:E25) -> 27 | H12: =SUM(total_consolidated_data!I20:I25) -> 21 | I12: =SUM(total_consolidated_data!J20:J25) -> 42 | J12: =COUNTA(_xlfn.UNIQUE(total_consolidated_data!F20:F25)) -> 4 | K12: One paper has 5 citations.
A13: =A12+1 -> 12 | B13: IoTSMS | C13: 2023 | D13: =COUNTA(total_consolidated_data!A8:A13) -> 6 | E13: =SUM(total_consolidated_data!H8:H13) -> 5 | F13: =SUM(total_consolidated_data!G8:G13) -> 202 | G13: =SUM(total_consolidated_data!E8:E13) -> 17 | H13: =SUM(total_consolidated_data!I8:I13) -> 7 | I13: =SUM(total_consolidated_data!J8:J13) -> 33 | J13: =COUNTA(_xlfn.UNIQUE(total_consolidated_data!F8:F13)) -> 5 | K13: One paper has 3 citations.
A14: =A13+1 -> 13 | B14: SenSys | C14: 2023 | D14: =COUNTA(total_consolidated_data!A54:A80) -> 27 | E14: =SUM(total_consolidated_data!H54:H80) -> 448 | F14: =SUM(total_consolidated_data!G54:G80) -> 2020 | G14: =SUM(total_consolidated_data!E54:E80) -> 139 | H14: =SUM(total_consolidated_data!I54:I80) -> 85 | I14: =SUM(total_consolidated_data!J54:J80) -> 450 | J14: =COUNTA(_xlfn.UNIQUE(total_consolidated_data!F54:F80)) -> 6 | K14: Three papers have citations above or equal to 40. Only two papers out of 27 are not cited.
A15: =A14+1 -> 14 | B15: SenSys | C15: 2024 | D15: =COUNTA(total_consolidated_data!A81:A114) -> 34 | E15: =SUM(total_consolidated_data!H81:H114) -> 401 | F15: =SUM(total_consolidated_data!G81:G114) -> 2588 | G15: =SUM(total_consolidated_data!E81:E114) -> 201 | H15: =SUM(total_consolidated_data!I81:I114) -> 108 | I15: =SUM(total_consolidated_data!J81:J114) -> 608 | J15: =COUNTA(_xlfn.UNIQUE(total_consolidated_data!F81:F114)) -> 8 | K15: Two papers have citations above 30. All the papers are cited atleast once.
A16: =A15+1 -> 15 | B16: WF-IoT | C16: 2023 | D16: =COUNTA(total_consolidated_data!A42:A47) -> 6 | E16: =SUM(total_consolidated_data!H42:H47) -> 12 | F16: =SUM(total_consolidated_data!G42:G47) -> 154 | G16: =SUM(total_consolidated_data!E42:E47) -> 32 | H16: =SUM(total_consolidated_data!I42:I47) -> 7 | I16: =SUM(total_consolidated_data!J42:J47) -> 64 | J16: =COUNTA(_xlfn.UNIQUE(total_consolidated_data!F42:F47)) -> 5 | K16: One paper has 5 citations.
A17: =A16+1 -> 16 | B17: WF-IoT | C17: 2024 | D17: =COUNTA(total_consolidated_data!A115:A151) -> 37 | E17: =SUM(total_consolidated_data!H115:H151) -> 115 | F17: =SUM(total_consolidated_data!G115:G151) -> 705 | G17: =SUM(total_consolidated_data!E115:E151) -> 158 | H17: =SUM(total_consolidated_data!I115:I151) -> 54 | I17: =SUM(total_consolidated_data!J115:J151) -> 160 | J17: =COUNTA(_xlfn.UNIQUE(total_consolidated_data!F115:F151)) -> 13 | K17: One paper has 25 citations.
A18: Total | D18: =SUM(D2:D17) -> 252 | E18: =SUM(E2:E17) -> 1342 | F18: =SUM(F2:F17) -> 9815 | G18: =SUM(G2:G17) -> 1113 | H18: =SUM(H2:H17) -> 577 | I18: =SUM(I2:I17) -> 2286 | J18: =COUNTA(_xlfn.UNIQUE(total_consolidated_data!F2:F253)) -> 41
A21: Sl. No. | B21: Name of the Conference | C21: Year | D21: Avergae Citations | E21: Average Reference | F21: Average Authors | G21: No. of Graphs plus Tables | H21: Average of Graphs plus Tables
A22: 1 | B22: BIOTC | C22: 2023 | D22: =E2/D2 -> 2 | E22: =F2/D2 -> 20.5 | F22: =G2/D2 -> 3 | G22: =H2+I2 -> 32 | H22: =G22/D2 -> 5.3333333
A23: =A22+1 -> 2 | B23: BIOTC | C23: 2024 | D23: =E3/D3 -> 4.5 | E23: =F3/D3 -> 28.625 | F23: =G3/D3 -> 4.625 | G23: =H3+I3 -> 74 | H23: =G23/D3 -> 9.25
A24: =A23+1 -> 3 | B24: DCOSS-IoT | C24: 2023 | D24: =E4/D4 -> 12.166667 | E24: =F4/D4 -> 23.833333 | F24: =G4/D4 -> 6.5 | G24: =H4+I4 -> 51 | H24: =G24/D4 -> 8.5
A25: =A24+1 -> 4 | B25: DCOSS-IoT | C25: 2024 | D25: =E5/D5 -> 6.2142857 | E25: =F5/D5 -> 27.857143 | F25: =G5/D5 -> 3.3928571 | G25: =H5+I5 -> 245 | H25: =G25/D5 -> 8.75
A26: =A25+1 -> 5 | B26: EAI HealthyIOT | C26: 2023 | D26: =E6/D6 -> 0.66666667 | E26: =F6/D6 -> 40.166667 | F26: =G6/D6 -> 3.1666667 | G26: =H6+I6 -> 29 | H26: =G26/D6 -> 4.8333333
A27: =A26+1 -> 6 | B27: EWSN | C27: 2023 | D27: =E7/D7 -> 0.054054054 | E27: =F7/D7 -> 27.297297 | F27: =G7/D7 -> 3.7027027 | G27: =H7+I7 -> 332 | H27: =G27/D7 -> 8.972973
A28: =A27+1 -> 7 | B28: EWSN | C28: 2024 | D28: =E8/D8 -> 0.2 | E28: =F8/D8 -> 37.95 | F28: =G8/D8 -> 4.4 | G28: =H8+I8 -> 282 | H28: =G28/D8 -> 14.1
A29: =A28+1 -> 8 | B29: ICIOT | C29: 2023 | D29: =E9/D9 -> 0.66666667 | E29: =F9/D9 -> 27.333333 | F29: =G9/D9 -> 4.5 | G29: =H9+I9 -> 39 | H29: =G29/D9 -> 6.5
A30: =A29+1 -> 9 | B30: ICIOT | C30: 2024 | D30: =E10/D10 -> 0.44444444 | E30: =F10/D10 -> 24.333333 | F30: =G10/D10 -> 5.2222222 | G30: =H10+I10 -> 71 | H30: =G30/D10 -> 7.8888889
A31: =A30+1 -> 10 | B31: IFIP-IoT | C31: 2023 | D31: =E11/D11 -> 3.7 | E31: =F11/D11 -> 27.7 | F31: =G11/D11 -> 3.2 | G31: =H11+I11 -> 69 | H31: =G31/D11 -> 6.9
A32: =A31+1 -> 11 | B32: IoTBDS | C32: 2023 | D32: =E12/D12 -> 1.8333333 | E32: =F12/D12 -> 33.5 | F32: =G12/D12 -> 4.5 | G32: =H12+I12 -> 63 | H32: =G32/D12 -> 10.5
A33: =A32+1 -> 12 | B33: IoTSMS | C33: 2023 | D33: =E13/D13 -> 0.83333333 | E33: =F13/D13 -> 33.666667 | F33: =G13/D13 -> 2.8333333 | G33: =H13+I13 -> 40 | H33: =G33/D13 -> 6.6666667
A34: =A33+1 -> 13 | B34: SenSys | C34: 2023 | D34: =E14/D14 -> 16.592593 | E34: =F14/D14 -> 74.814815 | F34: =G14/D14 -> 5.1481481 | G34: =H14+I14 -> 535 | H34: =G34/D14 -> 19.814815
... A37: =A36+1 -> 16 | B37: WF-IoT | C37: 2024 | D37: =E17/D17 -> 3.1081081 | E37: =F17/D17 -> 19.054054 | F37: =G17/D17 -> 4.2702703 | G37: =H17+I17 -> 214 | H37: =G37/D17 -> 5.7837838
A44: Sl. No. | B44: Name of the Conference | C44: Year | D44: Citation Impact Score | E44: Diversity Score | F44: Reference Quality Score | G44: Collaboration Score | H44: Visual Communication Score
A45: 1 | B45: BIOTC | C45: 2023 | D45: =D22/MAX(D22:D37) -> 0.12053571 | E45: =J2/MAX(J2:J17) -> 0.27777778 | F45: =E22/MAX(E22:E37) -> 0.26931994 | G45: =F22/MAX(F22:F37) -> 0.46153846 | H45: =H22/MAX(H22:H37) -> 0.25325885
A46: =A45+1 -> 2 | B46: BIOTC | C46: 2024 | D46: =D23/MAX(D22:D37) -> 0.27120536 | E46: =J3/MAX(J2:J17) -> 0.33333333 | F46: =E23/MAX(E22:E37) -> 0.3760626 | G46: =F23/MAX(F22:F37) -> 0.71153846 | H46: =H23/MAX(H22:H37) -> 0.43924581
A47: =A46+1 -> 3 | B47: DCOSS-IoT | C47: 2023 | D47: =D24/MAX(D22:D37) -> 0.73325893 | E47: =J4/MAX(J2:J17) -> 0.27777778 | F47: =E24/MAX(E22:E37) -> 0.3131118 | G47: =F24/MAX(F22:F37) -> 1 | H47: =H24/MAX(H22:H37) -> 0.40363128
A48: =A47+1 -> 4 | B48: DCOSS-IoT | C48: 2024 | D48: =D25/MAX(D22:D37) -> 0.37452168 | E48: =J5/MAX(J2:J17) -> 0.72222222 | F48: =E25/MAX(E22:E37) -> 0.36597483 | G48: =F25/MAX(F22:F37) -> 0.52197802 | H48: =H25/MAX(H22:H37) -> 0.41550279
A49: =A48+1 -> 5 | B49: EAI HealthyIOT | C49: 2023 | D49: =D26/MAX(D22:D37) -> 0.040178571 | E49: =J6/MAX(J2:J17) -> 0.27777778 | F49: =E26/MAX(E22:E37) -> 0.52769191 | G49: =F26/MAX(F22:F37) -> 0.48717949 | H49: =H26/MAX(H22:H37) -> 0.22951583
A50: =A49+1 -> 6 | B50: EWSN | C50: 2023 | D50: =D27/MAX(D22:D37) -> 0.003257722 | E50: =J7/MAX(J2:J17) -> 1 | F50: =E27/MAX(E22:E37) -> 0.35861983 | G50: =F27/MAX(F22:F37) -> 0.56964657 | H50: =H27/MAX(H22:H37) -> 0.4260909
...
